<?xml version="1.0" ?>
<robot name="turtlebot3_waffle_pi" xmlns:xacro="http://ros.org/wiki/xacro">
  <xacro:include filename="$(find turtlebot3_description)/urdf/common_properties.xacro"/>
  <xacro:include filename="$(find turtlebot3_description)/urdf/common.xacro"/>
  <xacro:property name="M_PI" value="3.14159274"/>

  <!-- Root link -->
  <link name="base_footprint"/>

  <!-- Base joint -->
  <joint name="base_joint" type="fixed">
    <parent link="base_footprint"/>
    <child link="base_link" />
    <origin xyz="0 0 0.010" rpy="0 0 0"/>
  </joint>
  
  <!-- Base link -->
  <link name="base_link">
    <visual>
      <origin xyz="-0.064 0 0.0" rpy="0 0 0"/>
      <geometry>
        <mesh filename="package://turtlebot3_description/meshes/bases/waffle_pi_base.stl" scale="0.001 0.001 0.001"/>
      </geometry>
      <material name="light_black"/>
    </visual>

    <collision>
      <origin xyz="-0.064 0 0.047" rpy="0 0 0"/>
      <geometry>
        <box size="0.266 0.266 0.094"/>
      </geometry>
    </collision>

    <inertial>
      <origin xyz="0 0 0" rpy="0 0 0"/>
      <mass value="1.3729096e+00"/>
      <inertia ixx="8.7002718e-03" ixy="-4.7576583e-05" ixz="1.1160499e-04"
               iyy="8.6195418e-03" iyz="-3.5422299e-06"
               izz="1.4612727e-02" />
    </inertial>
  </link>

  <!-- Wheel left joint -->
  <!-- joint name="wheel_left_joint" type="fixed" -->
  <joint name="Left_wheel" type="continuous">
    <parent link="base_link"/>
    <child link="wheel_left_link"/>
    <!-- child link="Left_wheel"/ -->
    <origin xyz="0.0 0.144 0.023" rpy="-${M_PI/2} 0 0"/>
    <axis xyz="0 0 1"/>
  </joint>
  
  <!-- Wheel left link -->
  <link name="wheel_left_link">
  <!-- link name="Left_wheel" -->
    <visual>
      <origin xyz="0 0 0" rpy="${M_PI/2} 0 0"/>
      <geometry>
        <mesh filename="package://turtlebot3_description/meshes/wheels/left_tire.stl" scale="0.001 0.001 0.001"/>
      </geometry>
      <material name="dark"/>
    </visual>

    <collision>
      <origin xyz="0 0 0" rpy="0 0 0"/>
      <geometry>
        <cylinder length="0.018" radius="0.033"/>
      </geometry>
    </collision>

    <inertial>
      <origin xyz="0 0 0" />
      <mass value="2.8498940e-02" />
      <inertia ixx="1.1175580e-05" ixy="-4.2369783e-11" ixz="-5.9381719e-09"
               iyy="1.1192413e-05" iyz="-1.4400107e-11"
               izz="2.0712558e-05" />
      </inertial>
  </link>

  <!-- Wheel right joint -->
  <!-- joint name="wheel_right_joint" type="fixed" -->
  <joint name="Right_wheel" type="continuous">
    <parent link="base_link"/>
    <child link="wheel_right_link"/>
    <!-- child link="Right_wheel"/ -->
    <origin xyz="0.0 -0.144 0.023" rpy="-${M_PI/2} 0 0"/>
    <axis xyz="0 0 1"/>
  </joint>
  
  <!-- Wheel right link -->
  <link name="wheel_right_link">
  <!-- link name="Right_wheel" -->
    <visual>
      <origin xyz="0 0 0" rpy="${M_PI/2} 0 0"/>
      <geometry>
        <mesh filename="package://turtlebot3_description/meshes/wheels/right_tire.stl" scale="0.001 0.001 0.001"/>
      </geometry>
      <material name="dark"/>
    </visual>

    <collision>
      <origin xyz="0 0 0" rpy="0 0 0"/>
      <geometry>
        <cylinder length="0.018" radius="0.033"/>
      </geometry>
    </collision>

    <inertial>
      <origin xyz="0 0 0" />
      <mass value="2.8498940e-02" />
      <inertia ixx="1.1175580e-05" ixy="-4.2369783e-11" ixz="-5.9381719e-09"
               iyy="1.1192413e-05" iyz="-1.4400107e-11"
               izz="2.0712558e-05" />
      </inertial>
  </link>
  
  <!-- Transmission -->
  <xacro:joint_velocity_trans_v0 name="Left_wheel"/>
  <xacro:joint_velocity_trans_v0 name="Right_wheel"/>

  <!-- Caster back left joint -->
  <joint name="caster_back_left_joint" type="fixed">
    <parent link="base_link"/>
    <child link="caster_back_left_link"/>
    <origin xyz="-0.177 0.064 -0.004" rpy="-${M_PI/2} 0 0"/>
  </joint>

  <!-- Caster back left link -->
  <link name="caster_back_left_link">
    <collision>
      <origin xyz="0 0.001 0" rpy="0 0 0"/>
      <geometry>
        <box size="0.030 0.009 0.020"/>
      </geometry>
    </collision>

    <inertial>
      <origin xyz="0 0 0" />
      <mass value="0.005" />
      <inertia ixx="0.001" ixy="0.0" ixz="0.0"
               iyy="0.001" iyz="0.0"
               izz="0.001" />
    </inertial>
  </link>

  <!-- Caster back right joint -->
  <joint name="caster_back_right_joint" type="fixed">
    <parent link="base_link"/>
    <child link="caster_back_right_link"/>
    <origin xyz="-0.177 -0.064 -0.004" rpy="-${M_PI/2} 0 0"/>
  </joint>

  <!-- Caster back right link -->
  <link name="caster_back_right_link">
    <collision>
      <origin xyz="0 0.001 0" rpy="0 0 0"/>
      <geometry>
        <box size="0.030 0.009 0.020"/>
      </geometry>
    </collision>

    <inertial>
      <origin xyz="0 0 0" />
      <mass value="0.005" />
      <inertia ixx="0.001" ixy="0.0" ixz="0.0"
               iyy="0.001" iyz="0.0"
               izz="0.001" />
    </inertial>
  </link>

  <!-- Sensors -->
  <!-- LiDAR joint -->
  <joint name="LiDAR_joint" type="fixed">
    <parent link="base_link"/>
    <child link="LiDAR"/>
    <!-- origin xyz="-0.064 0 0.122" rpy="${M_PI/2} 0 -${M_PI/2}" / -->
    <origin xyz="0 0 0" rpy="0 0 0" />
  </joint>

  <!-- LiDAR link -->
  <link name="LiDAR">
    <visual>
      <!-- origin xyz="0 0 0.0" rpy="-${M_PI/2} ${M_PI/2} 0"/ -->
      <origin xyz="-0.064 0 0.122" rpy="0 0 0"/>
      <geometry>
        <mesh filename="package://turtlebot3_description/meshes/sensors/lds.stl" scale="0.001 0.001 0.001"/>
      </geometry>
      <material name="dark"/>
    </visual>

    <collision>
      <!-- origin xyz="0.015 0 -0.0065" rpy="-${M_PI/2} ${M_PI/2} 0"/ -->
      <origin xyz="-0.064 0 0.122" rpy="0 0 0" />
      <geometry>
        <cylinder length="0.0315" radius="0.055"/>
      </geometry>
    </collision>

    <inertial>
      <mass value="0.114" />
      <origin xyz="0 0 0" />
      <inertia ixx="0.001" ixy="0.0" ixz="0.0"
               iyy="0.001" iyz="0.0"
               izz="0.001" />
    </inertial>
  </link>
  
  <!-- RealSense joint -->
  <joint name="RealSense_joint" type="fixed">
    <!-- origin xyz="0.076 -0.0665 0.09" rpy="-${M_PI/2} 0 -${M_PI/2}" / -->
    <origin xyz="0.076 -0.0665 0.09" rpy="${M_PI/2} 0 -${M_PI/2}" />
    <parent link="base_link"/>
    <child link ="RealSense"/>
  </joint>

  <!-- RealSense link -->
  <link name="RealSense">
    <visual>
      <origin xyz="0 0 0" rpy="0 ${M_PI} 0"/>
      <geometry>
        <mesh filename="package://turtlebot3_description/meshes/sensors/r200.dae"/>
      </geometry>
      <material name="blue"/>
    </visual>
    <collision>
      <origin xyz="0 0 0" rpy="0 ${M_PI} 0"/>
      <geometry>
        <mesh filename="package://turtlebot3_description/meshes/sensors/r200.dae"/>
      </geometry>
    </collision>
  </link>

  <!-- Imu joint -->
  <joint name="imu_joint" type="fixed">
    <parent link="base_link"/>
    <child link="Imu"/>
    <origin xyz="0.0 0 0.068" rpy="0 0 0"/>
  </joint>

  <!-- Imu link -->
  <link name="Imu"/>

  <!-- Camera joint -->
  <joint name="camera_joint" type="fixed">
    <origin xyz="0.073 -0.011 0.084" rpy="0 0 0"/>
    <parent link="base_link"/>
    <child link="camera_link"/>
  </joint>

  <!-- Camera link -->
  <link name="camera_link">
    <collision>
      <origin xyz="0.005 0.011 0.013" rpy="0 0 0"/>
      <geometry>
        <box size="0.015 0.030 0.027"/>
      </geometry>
    </collision>
  </link>

  <!-- RGB camera joint -->
  <joint name="camera_rgb_joint" type="fixed">
    <origin xyz="0.003 0.011 0.009" rpy="0 0 0"/>
    <parent link="camera_link"/>
    <child link="camera_rgb_frame"/>
  </joint>

  <!-- RGB camera link -->
  <link name="camera_rgb_frame"/>

  <!-- Optical RGB camera joint -->
  <joint name="camera_rgb_optical_joint" type="fixed">
    <origin xyz="0 0 0" rpy="-${M_PI/2} 0 -${M_PI/2}"/>
    <parent link="camera_rgb_frame"/>
    <child link="camera_rgb_optical_frame"/>
  </joint>
  <!-- Optical RGB camera link -->
  <link name="camera_rgb_optical_frame"/>

</robot>
